Workbook
Name Slicer_ProductName: #N/A
Name Slicer_Region_Clean: #N/A

Sheet Instructions
A1: EXCEL SKILLS TEST
A2: Retail Orders Analysis | Time: 90 minutes | Total: 100 marks (+5 bonus)
A4: RULES
A5: 1. Save this file as YourName_ExcelTest.xlsx before you start.
A6: 2. Use FORMULAS for every calculated cell — typed numbers get zero marks.
A7: 3. Do not edit columns A–I of Orders, except where a task says so. Your work goes in the yellow columns J–W and the yellow cells on Summary.
A8: 4. After cleaning (Section A), use the CLEAN columns (J, K, L) for all later tasks.
A9: 5. Sheets: Orders (main data), Products, Customers, Commission (lookup tables), Summary (answers), Pivot_Charts (Section D).
A10: 6. The data is messy on purpose — find the problems before they find you.
A12: SECTION A — DATA CLEANING (15 marks)
A13: No. | B13: Task | C13: Where | D13: Marks
A14: A1 | B14: Orders contains duplicate rows (same OrderID repeated). Remove the duplicates using Data > Remove Duplicates on OrderID. Type how many rows were removed in Summary!B4. | C14: Orders, Summary!B4 | D14: 4
A15: A2 | B15: Salesperson (F) and Region (E) have extra spaces and mixed capitalisation. In column J (Salesperson_Clean) and K (Region_Clean) use TRIM and PROPER to clean them. | C15: J, K | D15: 4
A16: A3 | B16: Blank cells in Discount (H) mean 'no discount'. Replace every blank with 0 using Go To Special > Blanks. | C16: H | D16: 3
A17: A4 | B17: Some ProductIDs (D) contain hidden spaces, which breaks lookups. In column L (ProductID_Clean) use TRIM to fix them. | C17: L | D17: 4
A19: SECTION B — LOOKUP FUNCTIONS (25 marks)
A20: No. | B20: Task | C20: Where | D20: Marks
A21: B1 | B21: In column M (ProductName) use VLOOKUP with exact match to fetch the product name from the Products sheet, using ProductID_Clean (L). | C21: M | D21: 5
A22: B2 | B22: In column N (Category) and O (UnitPrice) use VLOOKUP to fetch Category and UnitPrice from the Products sheet. | C22: N, O | D22: 4
A23: B3 | B23: Some ProductIDs do not exist in the Products sheet and return a not-found error. Wrap your B1/B2 formulas in IFERROR so ProductName shows "Unknown Product", Category shows "Unknown" and UnitPrice shows 0. | C23: M, N, O | D23: 4
A24: B4 | B24: In column P (CustomerCity) use INDEX + MATCH (not VLOOKUP) to fetch the customer's City from the Customers sheet using CustomerID. | C24: P | D24: 6
A25: B5 | B25: In column T (CommissionPct) use VLOOKUP with APPROXIMATE match (TRUE) on the Commission sheet to find the commission % for each order's Revenue (Q). | C25: T | D25: 6
A27: SECTION C — FORMULAS & SUMMARY (25 marks)
A28: No. | B28: Task | C28: Where | D28: Marks
A29: C1 | B29: In column Q (Revenue) calculate: Quantity × UnitPrice × (1 − Discount). | C29: Q | D29: 3
A30: C2 | B30: In column R (Month) show the month and year of OrderDate as text, e.g. Mar-2024, using the TEXT function. | C30: R | D30: 3
A31: C3 | B31: In column S (OrderSize) use a nested IF: Revenue ≥ 50,000 = "Large"; ≥ 20,000 = "Medium"; otherwise "Small". | C31: S | D31: 4
A32: C4 | B32: In column U (CommissionAmt) calculate Revenue × CommissionPct. | C32: U | D32: 2
A33: C5 | B33: In column V (FollowUp) use IF with AND: show "Follow Up" if PaymentStatus is "Pending" AND Revenue > 20,000; otherwise "OK". | C33: V | D33: 4
A34: C6 | B34: On Summary, fill the Region table: Total Revenue using SUMIFS and No. of Orders using COUNTIFS for each region (use Region_Clean, column K). | C34: Summary B8:C11 | D34: 5
A35: C7 | B35: On Summary, fill Avg Revenue per Order using AVERAGEIFS for each region, and the Grand Total row using SUM. | C35: Summary D8:D11, row 12 | D35: 4
A37: SECTION D — PIVOTTABLES & CHARTS (20 marks) — build on the Pivot_Charts sheet
A38: No. | B38: Task | C38: Where | D38: Marks
A39: D1 | B39: Create a PivotTable showing Total Revenue by Region_Clean. | C39: Pivot_Charts | D39: 4
A40: D2 | B40: Create a second PivotTable: Category in rows, Months in columns (group OrderDate by Months), Revenue as values. | C40: Pivot_Charts | D40: 5
A41: D3 | B41: Create a third PivotTable showing the Top 5 Salesperson_Clean by Revenue (Value Filters > Top 10 > 5). | C41: Pivot_Charts | D41: 4
A42: D4 | B42: Add a Slicer for Region_Clean and connect it to your PivotTables. | C42: Pivot_Charts | D42: 3
A43: D5 | B43: Insert a column chart (Revenue by Region) and a line chart (monthly Revenue trend). Add chart titles and axis labels. | C43: Pivot_Charts | D43: 4
A45: SECTION E — PRODUCTIVITY & FORMATTING (15 marks)
A46: No. | B46: Task | C46: Where | D46: Marks
...

Sheet Orders
A1: OrderID | B1: OrderDate | C1: CustomerID | D1: ProductID | E1: Region | F1: Salesperson | G1: Quantity | H1: Discount | I1: PaymentStatus | J1: Salesperson_Clean | K1: Region_Clean | L1: ProductID_Clean | M1: ProductName | N1: Category | O1: UnitPrice | P1: CustomerCity | Q1: Revenue | R1: Month | S1: OrderSize | T1: CommissionPct | U1: CommissionAmt | V1: FollowUp | W1: Segment_BONUS
A2: ORD2168 | B2: 45308 | C2: C1002 | D2: P104 | E2: North | F2: Kiran Shah | G2: 6 | H2: 0 | I2: Paid | J2: =PROPER(TRIM(F2)) -> Kiran Shah | K2: =PROPER(TRIM(E2)) -> North | L2: =TRIM(D2) -> P104 | M2: =IFERROR(VLOOKUP(L2,Products!$A$2:$D$21,2,FALSE),"Unknown Product") -> Tablet | N2: =IFERROR(VLOOKUP(L2,Products!$A$2:$D$21,3,0),"Unknown ") -> Electronics | O2: =IFERROR(VLOOKUP(L2,Products!$A$2:$D$21,4,0),0) -> 32000 | P2: =IFERROR(INDEX(Customers!$C$2:$C$41,MATCH(C2,Customers!$A$2:$A$41,0)),"Unknown City") -> Pune | Q2: =G2*O2*(1-H2) -> 192000 | R2: =TEXT(B2,"mmm-yyyy") -> Jan-2024 | S2: =IF(Q2>=50000,"Large",IF(Q2>=20000,"Medium","Small")) -> Large | T2: =VLOOKUP(Q2,Commission!$A$2:$B$6,2,TRUE) -> 0.06 | U2: =Q2*T2 -> 11520 | V2: =IF(AND(I2="Pending",Q2>20000),"Follow Up","OK") -> OK | W2: =_xlfn.XLOOKUP(C2,Customers!$A$2:$A$41,Customers!$D$2:$D$41) -> Home Office
A3: ORD2164 | B3: 45620 | C3: C1014 | D3: P999 | E3: North | F3: Kiran Shah | G3: 5 | H3: 0 | I3: Paid | J3: =PROPER(TRIM(F3)) -> Kiran Shah | K3: =PROPER(TRIM(E3)) -> North | L3: =TRIM(D3) -> P999 | M3: =IFERROR(VLOOKUP(L3,Products!$A$2:$D$21,2,FALSE),"Unknown Product") -> Unknown Product | N3: =IFERROR(VLOOKUP(L3,Products!$A$2:$D$21,3,0),"Unknown ") -> Unknown | O3: =IFERROR(VLOOKUP(L3,Products!$A$2:$D$21,4,0),0) -> 0 | P3: =IFERROR(INDEX(Customers!$C$2:$C$41,MATCH(C3,Customers!$A$2:$A$41,0)),"Unknown City") -> Delhi | Q3: =G3*O3*(1-H3) -> 0 | R3: =TEXT(B3,"mmm-yyyy") -> Nov-2024 | S3: =IF(Q3>=50000,"Large",IF(Q3>=20000,"Medium","Small")) -> Small | T3: =VLOOKUP(Q3,Commission!$A$2:$B$6,2,TRUE) -> 0.02 | U3: =Q3*T3 -> 0 | V3: =IF(AND(I3="Pending",Q3>20000),"Follow Up","OK") -> OK | W3: =_xlfn.XLOOKUP(C3,Customers!$A$2:$A$41,Customers!$D$2:$D$41) -> Consumer
A4: ORD2001 | B4: 45410 | C4: C1010 | D4: P103 | E4: South | F4: Kiran Shah | G4: 4 | H4: 0.15 | I4: Paid | J4: =PROPER(TRIM(F4)) -> Kiran Shah | K4: =PROPER(TRIM(E4)) -> South | L4: =TRIM(D4) -> P103 | M4: =IFERROR(VLOOKUP(L4,Products!$A$2:$D$21,2,FALSE),"Unknown Product") -> Headphones | N4: =IFERROR(VLOOKUP(L4,Products!$A$2:$D$21,3,0),"Unknown ") -> Electronics | O4: =IFERROR(VLOOKUP(L4,Products!$A$2:$D$21,4,0),0) -> 3500 | P4: =IFERROR(INDEX(Customers!$C$2:$C$41,MATCH(C4,Customers!$A$2:$A$41,0)),"Unknown City") -> Pune | Q4: =G4*O4*(1-H4) -> 11900 | R4: =TEXT(B4,"mmm-yyyy") -> Apr-2024 | S4: =IF(Q4>=50000,"Large",IF(Q4>=20000,"Medium","Small")) -> Small | T4: =VLOOKUP(Q4,Commission!$A$2:$B$6,2,TRUE) -> 0.03 | U4: =Q4*T4 -> 357 | V4: =IF(AND(I4="Pending",Q4>20000),"Follow Up","OK") -> OK | W4: =_xlfn.XLOOKUP(C4,Customers!$A$2:$A$41,Customers!$D$2:$D$41) -> Consumer
A5: ORD2181 | B5: 45511 | C5: C1035 | D5: P117 | E5: South | F5: Faisal Khan | G5: 4 | H5: 0.05 | I5: Paid | J5: =PROPER(TRIM(F5)) -> Faisal Khan | K5: =PROPER(TRIM(E5)) -> South | L5: =TRIM(D5) -> P117 | M5: =IFERROR(VLOOKUP(L5,Products!$A$2:$D$21,2,FALSE),"Unknown Product") -> T-Shirt Pack | N5: =IFERROR(VLOOKUP(L5,Products!$A$2:$D$21,3,0),"Unknown ") -> Clothing | O5: =IFERROR(VLOOKUP(L5,Products!$A$2:$D$21,4,0),0) -> 1500 | P5: =IFERROR(INDEX(Customers!$C$2:$C$41,MATCH(C5,Customers!$A$2:$A$41,0)),"Unknown City") -> Mumbai | Q5: =G5*O5*(1-H5) -> 5700 | R5: =TEXT(B5,"mmm-yyyy") -> Aug-2024 | S5: =IF(Q5>=50000,"Large",IF(Q5>=20000,"Medium","Small")) -> Small | T5: =VLOOKUP(Q5,Commission!$A$2:$B$6,2,TRUE) -> 0.02 | U5: =Q5*T5 -> 114 | V5: =IF(AND(I5="Pending",Q5>20000),"Follow Up","OK") -> OK | W5: =_xlfn.XLOOKUP(C5,Customers!$A$2:$A$41,Customers!$D$2:$D$41) -> Home Office
A6: ORD2176 | B6: 45379 | C6: C1028 | D6: P101 | E6: South | F6: Manoj Das | G6: 1 | H6: 0 | I6: Paid | J6: =PROPER(TRIM(F6)) -> Manoj Das | K6: =PROPER(TRIM(E6)) -> South | L6: =TRIM(D6) -> P101 | M6: =IFERROR(VLOOKUP(L6,Products!$A$2:$D$21,2,FALSE),"Unknown Product") -> Laptop | N6: =IFERROR(VLOOKUP(L6,Products!$A$2:$D$21,3,0),"Unknown ") -> Electronics | O6: =IFERROR(VLOOKUP(L6,Products!$A$2:$D$21,4,0),0) -> 55000 | P6: =IFERROR(INDEX(Customers!$C$2:$C$41,MATCH(C6,Customers!$A$2:$A$41,0)),"Unknown City") -> Bengaluru | Q6: =G6*O6*(1-H6) -> 55000 | R6: =TEXT(B6,"mmm-yyyy") -> Mar-2024 | S6: =IF(Q6>=50000,"Large",IF(Q6>=20000,"Medium","Small")) -> Large | T6: =VLOOKUP(Q6,Commission!$A$2:$B$6,2,TRUE) -> 0.05 | U6: =Q6*T6 -> 2750 | V6: =IF(AND(I6="Pending",Q6>20000),"Follow Up","OK") -> OK | W6: =_xlfn.XLOOKUP(C6,Customers!$A$2:$A$41,Customers!$D$2:$D$41) -> Consumer
A7: ORD2048 | B7: 45551 | C7: C1019 | D7: P120 | E7: South | F7: Manoj Das | G7: 1 | H7: 0.05 | I7: Paid | J7: =PROPER(TRIM(F7)) -> Manoj Das | K7: =PROPER(TRIM(E7)) -> South | L7: =TRIM(D7) -> P120 | M7: =IFERROR(VLOOKUP(L7,Products!$A$2:$D$21,2,FALSE),"Unknown Product") -> Printer Paper | N7: =IFERROR(VLOOKUP(L7,Products!$A$2:$D$21,3,0),"Unknown ") -> Stationery | O7: =IFERROR(VLOOKUP(L7,Products!$A$2:$D$21,4,0),0) -> 620 | P7: =IFERROR(INDEX(Customers!$C$2:$C$41,MATCH(C7,Customers!$A$2:$A$41,0)),"Unknown City") -> Pune | Q7: =G7*O7*(1-H7) -> 589 | R7: =TEXT(B7,"mmm-yyyy") -> Sep-2024 | S7: =IF(Q7>=50000,"Large",IF(Q7>=20000,"Medium","Small")) -> Small | T7: =VLOOKUP(Q7,Commission!$A$2:$B$6,2,TRUE) -> 0.02 | U7: =Q7*T7 -> 11.78 | V7: =IF(AND(I7="Pending",Q7>20000),"Follow Up","OK") -> OK | W7: =_xlfn.XLOOKUP(C7,Customers!$A$2:$A$41,Customers!$D$2:$D$41) -> Consumer
A8: ORD2078 | B8: 45330 | C8: C1014 | D8: P117 | E8: West | F8: Pooja Nair | G8: 8 | H8: 0 | I8: Pending | J8: =PROPER(TRIM(F8)) -> Pooja Nair | K8: =PROPER(TRIM(E8)) -> West | L8: =TRIM(D8) -> P117 | M8: =IFERROR(VLOOKUP(L8,Products!$A$2:$D$21,2,FALSE),"Unknown Product") -> T-Shirt Pack | N8: =IFERROR(VLOOKUP(L8,Products!$A$2:$D$21,3,0),"Unknown ") -> Clothing | O8: =IFERROR(VLOOKUP(L8,Products!$A$2:$D$21,4,0),0) -> 1500 | P8: =IFERROR(INDEX(Customers!$C$2:$C$41,MATCH(C8,Customers!$A$2:$A$41,0)),"Unknown City") -> Delhi | Q8: =G8*O8*(1-H8) -> 12000 | R8: =TEXT(B8,"mmm-yyyy") -> Feb-2024 | S8: =IF(Q8>=50000,"Large",IF(Q8>=20000,"Medium","Small")) -> Small | T8: =VLOOKUP(Q8,Commission!$A$2:$B$6,2,TRUE) -> 0.03 | U8: =Q8*T8 -> 360 | V8: =IF(AND(I8="Pending",Q8>20000),"Follow Up","OK") -> OK | W8: =_xlfn.XLOOKUP(C8,Customers!$A$2:$A$41,Customers!$D$2:$D$41) -> Consumer
A9: ORD2021 | B9: 45306 | C9: C1017 | D9: P107 | E9: East | F9: POOJA NAIR | G9: 10 | H9: 0 | I9: Paid | J9: =PROPER(TRIM(F9)) -> Pooja Nair | K9: =PROPER(TRIM(E9)) -> East | L9: =TRIM(D9) -> P107 | M9: =IFERROR(VLOOKUP(L9,Products!$A$2:$D$21,2,FALSE),"Unknown Product") -> Standing Desk | N9: =IFERROR(VLOOKUP(L9,Products!$A$2:$D$21,3,0),"Unknown ") -> Furniture | O9: =IFERROR(VLOOKUP(L9,Products!$A$2:$D$21,4,0),0) -> 18000 | P9: =IFERROR(INDEX(Customers!$C$2:$C$41,MATCH(C9,Customers!$A$2:$A$41,0)),"Unknown City") -> Pune | Q9: =G9*O9*(1-H9) -> 180000 | R9: =TEXT(B9,"mmm-yyyy") -> Jan-2024 | S9: =IF(Q9>=50000,"Large",IF(Q9>=20000,"Medium","Small")) -> Large | T9: =VLOOKUP(Q9,Commission!$A$2:$B$6,2,TRUE) -> 0.06 | U9: =Q9*T9 -> 10800 | V9: =IF(AND(I9="Pending",Q9>20000),"Follow Up","OK") -> OK | W9: =_xlfn.XLOOKUP(C9,Customers!$A$2:$A$41,Customers!$D$2:$D$41) -> Corporate
A10: ORD2012 | B10: 45377 | C10: C1023 | D10: P108 | E10: East | F10: Pooja Nair | G10: 10 | H10: 0 | I10: Paid | J10: =PROPER(TRIM(F10)) -> Pooja Nair | K10: =PROPER(TRIM(E10)) -> East | L10: =TRIM(D10) -> P108 | M10: =IFERROR(VLOOKUP(L10,Products!$A$2:$D$21,2,FALSE),"Unknown Product") -> Bookshelf | N10: =IFERROR(VLOOKUP(L10,Products!$A$2:$D$21,3,0),"Unknown ") -> Furniture | O10: =IFERROR(VLOOKUP(L10,Products!$A$2:$D$21,4,0),0) -> 6200 | P10: =IFERROR(INDEX(Customers!$C$2:$C$41,MATCH(C10,Customers!$A$2:$A$41,0)),"Unknown City") -> Hyderabad | Q10: =G10*O10*(1-H10) -> 62000 | R10: =TEXT(B10,"mmm-yyyy") -> Mar-2024 | S10: =IF(Q10>=50000,"Large",IF(Q10>=20000,"Medium","Small")) -> Large | T10: =VLOOKUP(Q10,Commission!$A$2:$B$6,2,TRUE) -> 0.05 | U10: =Q10*T10 -> 3100 | V10: =IF(AND(I10="Pending",Q10>20000),"Follow Up","OK") -> OK | W10: =_xlfn.XLOOKUP(C10,Customers!$A$2:$A$41,Customers!$D$2:$D$41) -> Corporate
A11: ORD2039 | B11: 45429 | C11: C1002 | D11: P103 | E11: East | F11: Sunita Rao | G11: 10 | H11: 0 | I11: Paid | J11: =PROPER(TRIM(F11)) -> Sunita Rao | K11: =PROPER(TRIM(E11)) -> East | L11: =TRIM(D11) -> P103 | M11: =IFERROR(VLOOKUP(L11,Products!$A$2:$D$21,2,FALSE),"Unknown Product") -> Headphones | N11: =IFERROR(VLOOKUP(L11,Products!$A$2:$D$21,3,0),"Unknown ") -> Electronics | O11: =IFERROR(VLOOKUP(L11,Products!$A$2:$D$21,4,0),0) -> 3500 | P11: =IFERROR(INDEX(Customers!$C$2:$C$41,MATCH(C11,Customers!$A$2:$A$41,0)),"Unknown City") -> Pune | Q11: =G11*O11*(1-H11) -> 35000 | R11: =TEXT(B11,"mmm-yyyy") -> May-2024 | S11: =IF(Q11>=50000,"Large",IF(Q11>=20000,"Medium","Small")) -> Medium | T11: =VLOOKUP(Q11,Commission!$A$2:$B$6,2,TRUE) -> 0.04 | U11: =Q11*T11 -> 1400 | V11: =IF(AND(I11="Pending",Q11>20000),"Follow Up","OK") -> OK | W11: =_xlfn.XLOOKUP(C11,Customers!$A$2:$A$41,Customers!$D$2:$D$41) -> Home Office
A12: ORD2114 | B12: 45567 | C12: C1008 | D12: P110 | E12: East | F12: Manoj Das | G12: 10 | H12: 0 | I12: Paid | J12: =PROPER(TRIM(F12)) -> Manoj Das | K12: =PROPER(TRIM(E12)) -> East | L12: =TRIM(D12) -> P110 | M12: =IFERROR(VLOOKUP(L12,Products!$A$2:$D$21,2,FALSE),"Unknown Product") -> Coffee Beans | N12: =IFERROR(VLOOKUP(L12,Products!$A$2:$D$21,3,0),"Unknown ") -> Grocery | O12: =IFERROR(VLOOKUP(L12,Products!$A$2:$D$21,4,0),0) -> 650 | P12: =IFERROR(INDEX(Customers!$C$2:$C$41,MATCH(C12,Customers!$A$2:$A$41,0)),"Unknown City") -> Bengaluru | Q12: =G12*O12*(1-H12) -> 6500 | R12: =TEXT(B12,"mmm-yyyy") -> Oct-2024 | S12: =IF(Q12>=50000,"Large",IF(Q12>=20000,"Medium","Small")) -> Small | T12: =VLOOKUP(Q12,Commission!$A$2:$B$6,2,TRUE) -> 0.02 | U12: =Q12*T12 -> 130 | V12: =IF(AND(I12="Pending",Q12>20000),"Follow Up","OK") -> OK | W12: =_xlfn.XLOOKUP(C12,Customers!$A$2:$A$41,Customers!$D$2:$D$41) -> Home Office
A13: ORD2106 | B13: 45426 | C13: C1021 | D13: P998 | E13: East | F13: Amit Verma | G13: 10 | H13: 0.15 | I13: Paid | J13: =PROPER(TRIM(F13)) -> Amit Verma | K13: =PROPER(TRIM(E13)) -> East | L13: =TRIM(D13) -> P998 | M13: =IFERROR(VLOOKUP(L13,Products!$A$2:$D$21,2,FALSE),"Unknown Product") -> Unknown Product | N13: =IFERROR(VLOOKUP(L13,Products!$A$2:$D$21,3,0),"Unknown ") -> Unknown | O13: =IFERROR(VLOOKUP(L13,Products!$A$2:$D$21,4,0),0) -> 0 | P13: =IFERROR(INDEX(Customers!$C$2:$C$41,MATCH(C13,Customers!$A$2:$A$41,0)),"Unknown City") -> Chennai | Q13: =G13*O13*(1-H13) -> 0 | R13: =TEXT(B13,"mmm-yyyy") -> May-2024 | S13: =IF(Q13>=50000,"Large",IF(Q13>=20000,"Medium","Small")) -> Small | T13: =VLOOKUP(Q13,Commission!$A$2:$B$6,2,TRUE) -> 0.02 | U13: =Q13*T13 -> 0 | V13: =IF(AND(I13="Pending",Q13>20000),"Follow Up","OK") -> OK | W13: =_xlfn.XLOOKUP(C13,Customers!$A$2:$A$41,Customers!$D$2:$D$41) -> Corporate
... A201: ORD2065 | B201: 45440 | C201: C1030 | D201: P103 | E201: West | F201: Manoj Das | G201: 7 | H201: 0 | I201: Paid | J201: =PROPER(TRIM(F201)) -> Manoj Das | K201: =PROPER(TRIM(E201)) -> West | L201: =TRIM(D201) -> P103 | M201: =IFERROR(VLOOKUP(L201,Products!$A$2:$D$21,2,FALSE),"Unknown Product") -> Headphones | N201: =IFERROR(VLOOKUP(L201,Products!$A$2:$D$21,3,0),"Unknown ") -> Electronics | O201: =IFERROR(VLOOKUP(L201,Products!$A$2:$D$21,4,0),0) -> 3500 | P201: =IFERROR(INDEX(Customers!$C$2:$C$41,MATCH(C201,Customers!$A$2:$A$41,0)),"Unknown City") -> Kolkata | Q201: =G201*O201*(1-H201) -> 24500 | R201: =TEXT(B201,"mmm-yyyy") -> May-2024 | S201: =IF(Q201>=50000,"Large",IF(Q201>=20000,"Medium","Small")) -> Medium | T201: =VLOOKUP(Q201,Commission!$A$2:$B$6,2,TRUE) -> 0.03 | U201: =Q201*T201 -> 735 | V201: =IF(AND(I201="Pending",Q201>20000),"Follow Up","OK") -> OK | W201: =_xlfn.XLOOKUP(C201,Customers!$A$2:$A$41,Customers!$D$2:$D$41) -> Home Office

Sheet Products
A1: ProductID | B1: ProductName | C1: Category | D1: UnitPrice
A2: P101 | B2: Laptop | C2: Electronics | D2: 55000
A3: P102 | B3: Smartphone | C3: Electronics | D3: 28000
A4: P103 | B4: Headphones | C4: Electronics | D4: 3500
A5: P104 | B5: Tablet | C5: Electronics | D5: 32000
A6: P105 | B6: Smartwatch | C6: Electronics | D6: 9500
A7: P106 | B7: Office Chair | C7: Furniture | D7: 7500
A8: P107 | B8: Standing Desk | C8: Furniture | D8: 18000
A9: P108 | B9: Bookshelf | C9: Furniture | D9: 6200
A10: P109 | B10: Sofa Set | C10: Furniture | D10: 42000
A11: P110 | B11: Coffee Beans | C11: Grocery | D11: 650
A12: P111 | B12: Green Tea | C12: Grocery | D12: 420
A13: P112 | B13: Olive Oil | C13: Grocery | D13: 980
... A21: P120 | B21: Printer Paper | C21: Stationery | D21: 620

Sheet Customers
A1: CustomerID | B1: CustomerName | C1: City | D1: Segment
A2: C1001 | B2: Sneha Patel | C2: Chennai | D2: Home Office
A3: C1002 | B3: Aarav Iyer | C3: Pune | D3: Home Office
A4: C1003 | B4: Priya Gupta | C4: Hyderabad | D4: Consumer
A5: C1004 | B5: Arjun Reddy | C5: Bengaluru | D5: Consumer
A6: C1005 | B6: Karan Singh | C6: Bengaluru | D6: Consumer
A7: C1006 | B7: Priya Rao | C7: Chennai | D7: Consumer
A8: C1007 | B8: Suresh Menon | C8: Bengaluru | D8: Consumer
A9: C1008 | B9: Rahul Menon | C9: Bengaluru | D9: Home Office
A10: C1009 | B10: Divya Singh | C10: Bengaluru | D10: Consumer
A11: C1010 | B11: Aarav Rao | C11: Pune | D11: Consumer
A12: C1011 | B12: Vikram Singh | C12: Mumbai | D12: Home Office
... A41: C1040 | B41: Karan Gupta | C41: Kolkata | D41: Corporate

Sheet Commission
A1: Revenue From | B1: Commission %
A2: 0 | B2: 0.02
A3: 10000 | B3: 0.03
A4: 25000 | B4: 0.04
A5: 50000 | B5: 0.05
A6: 100000 | B6: 0.06

Sheet Summary
A1: SUMMARY SHEET — fill the yellow cells
A4: A1: Duplicate rows removed | B4: =9 -> 9
A7: Region | B7: Total Revenue | C7: No. of Orders | D7: Avg Revenue per Order
A8: North | B8: =SUMIFS(Orders!Q:Q,Orders!K:K,A8) -> 3440069 | C8: =COUNTIFS(Orders!K:K,A8) -> 49 | D8: =AVERAGEIFS(Orders!Q:Q,Orders!K:K,A8) -> 70205.49
A9: South | B9: =SUMIFS(Orders!Q:Q,Orders!K:K,A9) -> 1627541.5 | C9: =COUNTIFS(Orders!K:K,A9) -> 49 | D9: =AVERAGEIFS(Orders!Q:Q,Orders!K:K,A9) -> 33215.133
A10: East | B10: =SUMIFS(Orders!Q:Q,Orders!K:K,A10) -> 2513464.5 | C10: =COUNTIFS(Orders!K:K,A10) -> 46 | D10: =AVERAGEIFS(Orders!Q:Q,Orders!K:K,A10) -> 54640.533
A11: West | B11: =SUMIFS(Orders!Q:Q,Orders!K:K,A11) -> 4001330 | C11: =COUNTIFS(Orders!K:K,A11) -> 56 | D11: =AVERAGEIFS(Orders!Q:Q,Orders!K:K,A11) -> 71452.321
A12: Grand Total | B12: =SUM(B8:B11) -> 11582405 | C12: =SUM(C8:C11) -> 200 | D12: =B12/C12 -> 57912.025
A14: E3: Select Region (drop-down) | B14: East
A15: E3: Revenue for selected region | B15: =SUMIFS(Orders!Q:Q,Orders!K:K,B14) -> 2513464.5
A17: BONUS 2: Revenue of 'Large' orders in selected region | B17: =SUMIFS(Orders!Q:Q,Orders!K:K,B14,Orders!S:S,"Large") -> 2119100

Sheet Column Chart
A3: Region_Clean | B3: Total Revenue
A4: North | B4: 3440069
A5: Grand Total | B5: 3440069

Sheet Top 5 Sales
A1: Top 5 Salespersons by Revenue
A3: Salesperson_Clean | B3: Sum of Revenue
A4: Latha Menon | B4: 845049
A5: Kiran Shah | B5: 769560
A6: Sunita Rao | B6: 617676
A7: Amit Verma | B7: 551680
A8: Manoj Das | B8: 254935
A9: Grand Total | B9: 3038900

Sheet Line Chart
A3: Sum of Revenue
B4: Electronics | C4: Grand Total
A5: Feb-2024 | B5: 57000 | C5: 57000
A6: Mar-2024 | B6: 80750 | C6: 80750
A7: Aug-2024 | B7: 8550 | C7: 8550
A8: Oct-2024 | B8: 124450 | C8: 124450
A9: Dec-2024 | B9: 19000 | C9: 19000
A10: Grand Total | B10: 289750 | C10: 289750

Sheet DashBoard
